<?xml version="1.0" encoding="UTF-8"?>
<testng-results skipped="0" failed="10" ignored="0" total="10" passed="0">
  <reporter-output>
  </reporter-output>
  <suite name="Suite" duration-ms="176223" started-at="2018-04-20T09:01:42Z" finished-at="2018-04-20T09:04:38Z">
    <groups>
    </groups>
    <test name="Day1" duration-ms="20739" started-at="2018-04-20T09:01:42Z" finished-at="2018-04-20T09:02:03Z">
      <class name="com.testcases.Day1">
        <test-method status="FAIL" signature="test()[pri:0, instance:com.testcases.Day1@4678c730]" name="test" duration-ms="19225" started-at="2018-04-20T05:01:42Z" finished-at="2018-04-20T05:02:01Z">
          <exception class="java.lang.AssertionError">
            <message>
              <![CDATA[The following asserts failed:
	expected [52] but found [59],
	expected [Sunny] but found [Clear],
	expected [50] but found [43],
	expected [7] but found [8],
	Test Failed]]>
            </message>
            <full-stacktrace>
              <![CDATA[java.lang.AssertionError: The following asserts failed:
	expected [52] but found [59],
	expected [Sunny] but found [Clear],
	expected [50] but found [43],
	expected [7] but found [8],
	Test Failed
	at org.testng.asserts.SoftAssert.assertAll(SoftAssert.java:43)
	at com.testcases.Day1.test(Day1.java:203)
	at sun.reflect.NativeMethodAccessorImpl.invoke0(Native Method)
	at sun.reflect.NativeMethodAccessorImpl.invoke(Unknown Source)
	at sun.reflect.DelegatingMethodAccessorImpl.invoke(Unknown Source)
	at java.lang.reflect.Method.invoke(Unknown Source)
	at org.testng.internal.MethodInvocationHelper.invokeMethod(MethodInvocationHelper.java:104)
	at org.testng.internal.Invoker.invokeMethod(Invoker.java:645)
	at org.testng.internal.Invoker.invokeTestMethod(Invoker.java:851)
	at org.testng.internal.Invoker.invokeTestMethods(Invoker.java:1177)
	at org.testng.internal.TestMethodWorker.invokeTestMethods(TestMethodWorker.java:129)
	at org.testng.internal.TestMethodWorker.run(TestMethodWorker.java:112)
	at org.testng.TestRunner.privateRun(TestRunner.java:756)
	at org.testng.TestRunner.run(TestRunner.java:610)
	at org.testng.SuiteRunner.runTest(SuiteRunner.java:387)
	at org.testng.SuiteRunner.runSequentially(SuiteRunner.java:382)
	at org.testng.SuiteRunner.privateRun(SuiteRunner.java:340)
	at org.testng.SuiteRunner.run(SuiteRunner.java:289)
	at org.testng.SuiteRunnerWorker.runSuite(SuiteRunnerWorker.java:52)
	at org.testng.SuiteRunnerWorker.run(SuiteRunnerWorker.java:86)
	at org.testng.TestNG.runSuitesSequentially(TestNG.java:1293)
	at org.testng.TestNG.runSuitesLocally(TestNG.java:1218)
	at org.testng.TestNG.runSuites(TestNG.java:1133)
	at org.testng.TestNG.run(TestNG.java:1104)
	at org.testng.remote.AbstractRemoteTestNG.run(AbstractRemoteTestNG.java:114)
	at org.testng.remote.RemoteTestNG.initAndRun(RemoteTestNG.java:251)
	at org.testng.remote.RemoteTestNG.main(RemoteTestNG.java:77)
]]>
            </full-stacktrace>
          </exception> <!-- java.lang.AssertionError -->
          <reporter-output>
          </reporter-output>
        </test-method> <!-- test -->
        <test-method status="PASS" signature="closeBrowser()[pri:0, instance:com.testcases.Day1@4678c730]" name="closeBrowser" is-config="true" duration-ms="1497" started-at="2018-04-20T05:02:01Z" finished-at="2018-04-20T05:02:03Z">
          <reporter-output>
          </reporter-output>
        </test-method> <!-- closeBrowser -->
      </class> <!-- com.testcases.Day1 -->
    </test> <!-- Day1 -->
    <test name="Day2" duration-ms="16676" started-at="2018-04-20T09:02:03Z" finished-at="2018-04-20T09:02:20Z">
      <class name="com.testcases.Day2">
        <test-method status="FAIL" signature="test()[pri:0, instance:com.testcases.Day2@68c4039c]" name="test" duration-ms="15138" started-at="2018-04-20T05:02:03Z" finished-at="2018-04-20T05:02:18Z">
          <exception class="java.lang.AssertionError">
            <message>
              <![CDATA[The following asserts failed:
	expected [37] but found [39],
	expected [50] but found [55],
	expected [Cloudy] but found [Overcast],
	expected [56] but found [46],
	expected [6] but found [8]]]>
            </message>
            <full-stacktrace>
              <![CDATA[java.lang.AssertionError: The following asserts failed:
	expected [37] but found [39],
	expected [50] but found [55],
	expected [Cloudy] but found [Overcast],
	expected [56] but found [46],
	expected [6] but found [8]
	at org.testng.asserts.SoftAssert.assertAll(SoftAssert.java:43)
	at com.testcases.Day2.test(Day2.java:203)
	at sun.reflect.NativeMethodAccessorImpl.invoke0(Native Method)
	at sun.reflect.NativeMethodAccessorImpl.invoke(Unknown Source)
	at sun.reflect.DelegatingMethodAccessorImpl.invoke(Unknown Source)
	at java.lang.reflect.Method.invoke(Unknown Source)
	at org.testng.internal.MethodInvocationHelper.invokeMethod(MethodInvocationHelper.java:104)
	at org.testng.internal.Invoker.invokeMethod(Invoker.java:645)
	at org.testng.internal.Invoker.invokeTestMethod(Invoker.java:851)
	at org.testng.internal.Invoker.invokeTestMethods(Invoker.java:1177)
	at org.testng.internal.TestMethodWorker.invokeTestMethods(TestMethodWorker.java:129)
	at org.testng.internal.TestMethodWorker.run(TestMethodWorker.java:112)
	at org.testng.TestRunner.privateRun(TestRunner.java:756)
	at org.testng.TestRunner.run(TestRunner.java:610)
	at org.testng.SuiteRunner.runTest(SuiteRunner.java:387)
	at org.testng.SuiteRunner.runSequentially(SuiteRunner.java:382)
	at org.testng.SuiteRunner.privateRun(SuiteRunner.java:340)
	at org.testng.SuiteRunner.run(SuiteRunner.java:289)
	at org.testng.SuiteRunnerWorker.runSuite(SuiteRunnerWorker.java:52)
	at org.testng.SuiteRunnerWorker.run(SuiteRunnerWorker.java:86)
	at org.testng.TestNG.runSuitesSequentially(TestNG.java:1293)
	at org.testng.TestNG.runSuitesLocally(TestNG.java:1218)
	at org.testng.TestNG.runSuites(TestNG.java:1133)
	at org.testng.TestNG.run(TestNG.java:1104)
	at org.testng.remote.AbstractRemoteTestNG.run(AbstractRemoteTestNG.java:114)
	at org.testng.remote.RemoteTestNG.initAndRun(RemoteTestNG.java:251)
	at org.testng.remote.RemoteTestNG.main(RemoteTestNG.java:77)
]]>
            </full-stacktrace>
          </exception> <!-- java.lang.AssertionError -->
          <reporter-output>
          </reporter-output>
        </test-method> <!-- test -->
        <test-method status="PASS" signature="closeBrowser()[pri:0, instance:com.testcases.Day2@68c4039c]" name="closeBrowser" is-config="true" duration-ms="1535" started-at="2018-04-20T05:02:18Z" finished-at="2018-04-20T05:02:20Z">
          <reporter-output>
          </reporter-output>
        </test-method> <!-- closeBrowser -->
      </class> <!-- com.testcases.Day2 -->
    </test> <!-- Day2 -->
    <test name="Day3" duration-ms="16310" started-at="2018-04-20T09:02:20Z" finished-at="2018-04-20T09:02:36Z">
      <class name="com.testcases.Day3">
        <test-method status="FAIL" signature="test()[pri:0, instance:com.testcases.Day3@77caeb3e]" name="test" duration-ms="14786" started-at="2018-04-20T05:02:20Z" finished-at="2018-04-20T05:02:34Z">
          <exception class="java.lang.AssertionError">
            <message>
              <![CDATA[The following asserts failed:
	expected [50] but found [58],
	expected [62] but found [48],
	expected [12] but found [11],
	Test Failed]]>
            </message>
            <full-stacktrace>
              <![CDATA[java.lang.AssertionError: The following asserts failed:
	expected [50] but found [58],
	expected [62] but found [48],
	expected [12] but found [11],
	Test Failed
	at org.testng.asserts.SoftAssert.assertAll(SoftAssert.java:43)
	at com.testcases.Day3.test(Day3.java:203)
	at sun.reflect.NativeMethodAccessorImpl.invoke0(Native Method)
	at sun.reflect.NativeMethodAccessorImpl.invoke(Unknown Source)
	at sun.reflect.DelegatingMethodAccessorImpl.invoke(Unknown Source)
	at java.lang.reflect.Method.invoke(Unknown Source)
	at org.testng.internal.MethodInvocationHelper.invokeMethod(MethodInvocationHelper.java:104)
	at org.testng.internal.Invoker.invokeMethod(Invoker.java:645)
	at org.testng.internal.Invoker.invokeTestMethod(Invoker.java:851)
	at org.testng.internal.Invoker.invokeTestMethods(Invoker.java:1177)
	at org.testng.internal.TestMethodWorker.invokeTestMethods(TestMethodWorker.java:129)
	at org.testng.internal.TestMethodWorker.run(TestMethodWorker.java:112)
	at org.testng.TestRunner.privateRun(TestRunner.java:756)
	at org.testng.TestRunner.run(TestRunner.java:610)
	at org.testng.SuiteRunner.runTest(SuiteRunner.java:387)
	at org.testng.SuiteRunner.runSequentially(SuiteRunner.java:382)
	at org.testng.SuiteRunner.privateRun(SuiteRunner.java:340)
	at org.testng.SuiteRunner.run(SuiteRunner.java:289)
	at org.testng.SuiteRunnerWorker.runSuite(SuiteRunnerWorker.java:52)
	at org.testng.SuiteRunnerWorker.run(SuiteRunnerWorker.java:86)
	at org.testng.TestNG.runSuitesSequentially(TestNG.java:1293)
	at org.testng.TestNG.runSuitesLocally(TestNG.java:1218)
	at org.testng.TestNG.runSuites(TestNG.java:1133)
	at org.testng.TestNG.run(TestNG.java:1104)
	at org.testng.remote.AbstractRemoteTestNG.run(AbstractRemoteTestNG.java:114)
	at org.testng.remote.RemoteTestNG.initAndRun(RemoteTestNG.java:251)
	at org.testng.remote.RemoteTestNG.main(RemoteTestNG.java:77)
]]>
            </full-stacktrace>
          </exception> <!-- java.lang.AssertionError -->
          <reporter-output>
          </reporter-output>
        </test-method> <!-- test -->
        <test-method status="PASS" signature="closeBrowser()[pri:0, instance:com.testcases.Day3@77caeb3e]" name="closeBrowser" is-config="true" duration-ms="1521" started-at="2018-04-20T05:02:34Z" finished-at="2018-04-20T05:02:36Z">
          <reporter-output>
          </reporter-output>
        </test-method> <!-- closeBrowser -->
      </class> <!-- com.testcases.Day3 -->
    </test> <!-- Day3 -->
    <test name="Day4" duration-ms="20104" started-at="2018-04-20T09:02:36Z" finished-at="2018-04-20T09:02:56Z">
      <class name="com.testcases.Day4">
        <test-method status="FAIL" signature="test()[pri:0, instance:com.testcases.Day4@604ed9f0]" name="test" duration-ms="18572" started-at="2018-04-20T05:02:36Z" finished-at="2018-04-20T05:02:55Z">
          <exception class="java.lang.AssertionError">
            <message>
              <![CDATA[The following asserts failed:
	expected [52] but found [59],
	expected [Sunny] but found [Clear],
	expected [60] but found [51],
	expected [11] but found [10]]]>
            </message>
            <full-stacktrace>
              <![CDATA[java.lang.AssertionError: The following asserts failed:
	expected [52] but found [59],
	expected [Sunny] but found [Clear],
	expected [60] but found [51],
	expected [11] but found [10]
	at org.testng.asserts.SoftAssert.assertAll(SoftAssert.java:43)
	at com.testcases.Day4.test(Day4.java:203)
	at sun.reflect.NativeMethodAccessorImpl.invoke0(Native Method)
	at sun.reflect.NativeMethodAccessorImpl.invoke(Unknown Source)
	at sun.reflect.DelegatingMethodAccessorImpl.invoke(Unknown Source)
	at java.lang.reflect.Method.invoke(Unknown Source)
	at org.testng.internal.MethodInvocationHelper.invokeMethod(MethodInvocationHelper.java:104)
	at org.testng.internal.Invoker.invokeMethod(Invoker.java:645)
	at org.testng.internal.Invoker.invokeTestMethod(Invoker.java:851)
	at org.testng.internal.Invoker.invokeTestMethods(Invoker.java:1177)
	at org.testng.internal.TestMethodWorker.invokeTestMethods(TestMethodWorker.java:129)
	at org.testng.internal.TestMethodWorker.run(TestMethodWorker.java:112)
	at org.testng.TestRunner.privateRun(TestRunner.java:756)
	at org.testng.TestRunner.run(TestRunner.java:610)
	at org.testng.SuiteRunner.runTest(SuiteRunner.java:387)
	at org.testng.SuiteRunner.runSequentially(SuiteRunner.java:382)
	at org.testng.SuiteRunner.privateRun(SuiteRunner.java:340)
	at org.testng.SuiteRunner.run(SuiteRunner.java:289)
	at org.testng.SuiteRunnerWorker.runSuite(SuiteRunnerWorker.java:52)
	at org.testng.SuiteRunnerWorker.run(SuiteRunnerWorker.java:86)
	at org.testng.TestNG.runSuitesSequentially(TestNG.java:1293)
	at org.testng.TestNG.runSuitesLocally(TestNG.java:1218)
	at org.testng.TestNG.runSuites(TestNG.java:1133)
	at org.testng.TestNG.run(TestNG.java:1104)
	at org.testng.remote.AbstractRemoteTestNG.run(AbstractRemoteTestNG.java:114)
	at org.testng.remote.RemoteTestNG.initAndRun(RemoteTestNG.java:251)
	at org.testng.remote.RemoteTestNG.main(RemoteTestNG.java:77)
]]>
            </full-stacktrace>
          </exception> <!-- java.lang.AssertionError -->
          <reporter-output>
          </reporter-output>
        </test-method> <!-- test -->
        <test-method status="PASS" signature="closeBrowser()[pri:0, instance:com.testcases.Day4@604ed9f0]" name="closeBrowser" is-config="true" duration-ms="1530" started-at="2018-04-20T05:02:55Z" finished-at="2018-04-20T05:02:56Z">
          <reporter-output>
          </reporter-output>
        </test-method> <!-- closeBrowser -->
      </class> <!-- com.testcases.Day4 -->
    </test> <!-- Day4 -->
    <test name="Day5" duration-ms="17847" started-at="2018-04-20T09:02:56Z" finished-at="2018-04-20T09:03:14Z">
      <class name="com.testcases.Day5">
        <test-method status="FAIL" signature="test()[pri:0, instance:com.testcases.Day5@4883b407]" name="test" duration-ms="16338" started-at="2018-04-20T05:02:56Z" finished-at="2018-04-20T05:03:12Z">
          <exception class="java.lang.AssertionError">
            <message>
              <![CDATA[The following asserts failed:
	expected [54] but found [62],
	expected [77] but found [67],
	expected [E] but found [ENE]]]>
            </message>
            <full-stacktrace>
              <![CDATA[java.lang.AssertionError: The following asserts failed:
	expected [54] but found [62],
	expected [77] but found [67],
	expected [E] but found [ENE]
	at org.testng.asserts.SoftAssert.assertAll(SoftAssert.java:43)
	at com.testcases.Day5.test(Day5.java:203)
	at sun.reflect.NativeMethodAccessorImpl.invoke0(Native Method)
	at sun.reflect.NativeMethodAccessorImpl.invoke(Unknown Source)
	at sun.reflect.DelegatingMethodAccessorImpl.invoke(Unknown Source)
	at java.lang.reflect.Method.invoke(Unknown Source)
	at org.testng.internal.MethodInvocationHelper.invokeMethod(MethodInvocationHelper.java:104)
	at org.testng.internal.Invoker.invokeMethod(Invoker.java:645)
	at org.testng.internal.Invoker.invokeTestMethod(Invoker.java:851)
	at org.testng.internal.Invoker.invokeTestMethods(Invoker.java:1177)
	at org.testng.internal.TestMethodWorker.invokeTestMethods(TestMethodWorker.java:129)
	at org.testng.internal.TestMethodWorker.run(TestMethodWorker.java:112)
	at org.testng.TestRunner.privateRun(TestRunner.java:756)
	at org.testng.TestRunner.run(TestRunner.java:610)
	at org.testng.SuiteRunner.runTest(SuiteRunner.java:387)
	at org.testng.SuiteRunner.runSequentially(SuiteRunner.java:382)
	at org.testng.SuiteRunner.privateRun(SuiteRunner.java:340)
	at org.testng.SuiteRunner.run(SuiteRunner.java:289)
	at org.testng.SuiteRunnerWorker.runSuite(SuiteRunnerWorker.java:52)
	at org.testng.SuiteRunnerWorker.run(SuiteRunnerWorker.java:86)
	at org.testng.TestNG.runSuitesSequentially(TestNG.java:1293)
	at org.testng.TestNG.runSuitesLocally(TestNG.java:1218)
	at org.testng.TestNG.runSuites(TestNG.java:1133)
	at org.testng.TestNG.run(TestNG.java:1104)
	at org.testng.remote.AbstractRemoteTestNG.run(AbstractRemoteTestNG.java:114)
	at org.testng.remote.RemoteTestNG.initAndRun(RemoteTestNG.java:251)
	at org.testng.remote.RemoteTestNG.main(RemoteTestNG.java:77)
]]>
            </full-stacktrace>
          </exception> <!-- java.lang.AssertionError -->
          <reporter-output>
          </reporter-output>
        </test-method> <!-- test -->
        <test-method status="PASS" signature="closeBrowser()[pri:0, instance:com.testcases.Day5@4883b407]" name="closeBrowser" is-config="true" duration-ms="1507" started-at="2018-04-20T05:03:12Z" finished-at="2018-04-20T05:03:14Z">
          <reporter-output>
          </reporter-output>
        </test-method> <!-- closeBrowser -->
      </class> <!-- com.testcases.Day5 -->
    </test> <!-- Day5 -->
    <test name="Day6" duration-ms="16941" started-at="2018-04-20T09:03:14Z" finished-at="2018-04-20T09:03:31Z">
      <class name="com.testcases.Day6">
        <test-method status="FAIL" signature="test()[pri:0, instance:com.testcases.Day6@5442a311]" name="test" duration-ms="15416" started-at="2018-04-20T05:03:14Z" finished-at="2018-04-20T05:03:29Z">
          <exception class="java.lang.AssertionError">
            <message>
              <![CDATA[The following asserts failed:
	expected [40] but found [38],
	expected [48] but found [51],
	expected [AM Showers] but found [Chance of Rain],
	expected [74] but found [66],
	expected [NNW] but found [NNE]]]>
            </message>
            <full-stacktrace>
              <![CDATA[java.lang.AssertionError: The following asserts failed:
	expected [40] but found [38],
	expected [48] but found [51],
	expected [AM Showers] but found [Chance of Rain],
	expected [74] but found [66],
	expected [NNW] but found [NNE]
	at org.testng.asserts.SoftAssert.assertAll(SoftAssert.java:43)
	at com.testcases.Day6.test(Day6.java:203)
	at sun.reflect.NativeMethodAccessorImpl.invoke0(Native Method)
	at sun.reflect.NativeMethodAccessorImpl.invoke(Unknown Source)
	at sun.reflect.DelegatingMethodAccessorImpl.invoke(Unknown Source)
	at java.lang.reflect.Method.invoke(Unknown Source)
	at org.testng.internal.MethodInvocationHelper.invokeMethod(MethodInvocationHelper.java:104)
	at org.testng.internal.Invoker.invokeMethod(Invoker.java:645)
	at org.testng.internal.Invoker.invokeTestMethod(Invoker.java:851)
	at org.testng.internal.Invoker.invokeTestMethods(Invoker.java:1177)
	at org.testng.internal.TestMethodWorker.invokeTestMethods(TestMethodWorker.java:129)
	at org.testng.internal.TestMethodWorker.run(TestMethodWorker.java:112)
	at org.testng.TestRunner.privateRun(TestRunner.java:756)
	at org.testng.TestRunner.run(TestRunner.java:610)
	at org.testng.SuiteRunner.runTest(SuiteRunner.java:387)
	at org.testng.SuiteRunner.runSequentially(SuiteRunner.java:382)
	at org.testng.SuiteRunner.privateRun(SuiteRunner.java:340)
	at org.testng.SuiteRunner.run(SuiteRunner.java:289)
	at org.testng.SuiteRunnerWorker.runSuite(SuiteRunnerWorker.java:52)
	at org.testng.SuiteRunnerWorker.run(SuiteRunnerWorker.java:86)
	at org.testng.TestNG.runSuitesSequentially(TestNG.java:1293)
	at org.testng.TestNG.runSuitesLocally(TestNG.java:1218)
	at org.testng.TestNG.runSuites(TestNG.java:1133)
	at org.testng.TestNG.run(TestNG.java:1104)
	at org.testng.remote.AbstractRemoteTestNG.run(AbstractRemoteTestNG.java:114)
	at org.testng.remote.RemoteTestNG.initAndRun(RemoteTestNG.java:251)
	at org.testng.remote.RemoteTestNG.main(RemoteTestNG.java:77)
]]>
            </full-stacktrace>
          </exception> <!-- java.lang.AssertionError -->
          <reporter-output>
          </reporter-output>
        </test-method> <!-- test -->
        <test-method status="PASS" signature="closeBrowser()[pri:0, instance:com.testcases.Day6@5442a311]" name="closeBrowser" is-config="true" duration-ms="1523" started-at="2018-04-20T05:03:29Z" finished-at="2018-04-20T05:03:31Z">
          <reporter-output>
          </reporter-output>
        </test-method> <!-- closeBrowser -->
      </class> <!-- com.testcases.Day6 -->
    </test> <!-- Day6 -->
    <test name="Day7" duration-ms="17221" started-at="2018-04-20T09:03:31Z" finished-at="2018-04-20T09:03:48Z">
      <class name="com.testcases.Day7">
        <test-method status="FAIL" signature="test()[pri:0, instance:com.testcases.Day7@146ba0ac]" name="test" duration-ms="15691" started-at="2018-04-20T05:03:31Z" finished-at="2018-04-20T05:03:47Z">
          <exception class="java.lang.AssertionError">
            <message>
              <![CDATA[The following asserts failed:
	expected [43] but found [44],
	expected [54] but found [61],
	expected [Mostly Sunny] but found [Clear],
	expected [62] but found [54]]]>
            </message>
            <full-stacktrace>
              <![CDATA[java.lang.AssertionError: The following asserts failed:
	expected [43] but found [44],
	expected [54] but found [61],
	expected [Mostly Sunny] but found [Clear],
	expected [62] but found [54]
	at org.testng.asserts.SoftAssert.assertAll(SoftAssert.java:43)
	at com.testcases.Day7.test(Day7.java:203)
	at sun.reflect.NativeMethodAccessorImpl.invoke0(Native Method)
	at sun.reflect.NativeMethodAccessorImpl.invoke(Unknown Source)
	at sun.reflect.DelegatingMethodAccessorImpl.invoke(Unknown Source)
	at java.lang.reflect.Method.invoke(Unknown Source)
	at org.testng.internal.MethodInvocationHelper.invokeMethod(MethodInvocationHelper.java:104)
	at org.testng.internal.Invoker.invokeMethod(Invoker.java:645)
	at org.testng.internal.Invoker.invokeTestMethod(Invoker.java:851)
	at org.testng.internal.Invoker.invokeTestMethods(Invoker.java:1177)
	at org.testng.internal.TestMethodWorker.invokeTestMethods(TestMethodWorker.java:129)
	at org.testng.internal.TestMethodWorker.run(TestMethodWorker.java:112)
	at org.testng.TestRunner.privateRun(TestRunner.java:756)
	at org.testng.TestRunner.run(TestRunner.java:610)
	at org.testng.SuiteRunner.runTest(SuiteRunner.java:387)
	at org.testng.SuiteRunner.runSequentially(SuiteRunner.java:382)
	at org.testng.SuiteRunner.privateRun(SuiteRunner.java:340)
	at org.testng.SuiteRunner.run(SuiteRunner.java:289)
	at org.testng.SuiteRunnerWorker.runSuite(SuiteRunnerWorker.java:52)
	at org.testng.SuiteRunnerWorker.run(SuiteRunnerWorker.java:86)
	at org.testng.TestNG.runSuitesSequentially(TestNG.java:1293)
	at org.testng.TestNG.runSuitesLocally(TestNG.java:1218)
	at org.testng.TestNG.runSuites(TestNG.java:1133)
	at org.testng.TestNG.run(TestNG.java:1104)
	at org.testng.remote.AbstractRemoteTestNG.run(AbstractRemoteTestNG.java:114)
	at org.testng.remote.RemoteTestNG.initAndRun(RemoteTestNG.java:251)
	at org.testng.remote.RemoteTestNG.main(RemoteTestNG.java:77)
]]>
            </full-stacktrace>
          </exception> <!-- java.lang.AssertionError -->
          <reporter-output>
          </reporter-output>
        </test-method> <!-- test -->
        <test-method status="PASS" signature="closeBrowser()[pri:0, instance:com.testcases.Day7@146ba0ac]" name="closeBrowser" is-config="true" duration-ms="1528" started-at="2018-04-20T05:03:47Z" finished-at="2018-04-20T05:03:48Z">
          <reporter-output>
          </reporter-output>
        </test-method> <!-- closeBrowser -->
      </class> <!-- com.testcases.Day7 -->
    </test> <!-- Day7 -->
    <test name="Day8" duration-ms="16243" started-at="2018-04-20T09:03:48Z" finished-at="2018-04-20T09:04:04Z">
      <class name="com.testcases.Day8">
        <test-method status="FAIL" signature="test()[pri:0, instance:com.testcases.Day8@598067a5]" name="test" duration-ms="14711" started-at="2018-04-20T05:03:48Z" finished-at="2018-04-20T05:04:03Z">
          <exception class="java.lang.AssertionError">
            <message>
              <![CDATA[The following asserts failed:
	expected [46] but found [43],
	expected [59] but found [63],
	expected [Mostly Sunny] but found [Clear],
	expected [60] but found [55],
	expected [11] but found [12],
	expected [SW] but found [NW],
	Test Failed]]>
            </message>
            <full-stacktrace>
              <![CDATA[java.lang.AssertionError: The following asserts failed:
	expected [46] but found [43],
	expected [59] but found [63],
	expected [Mostly Sunny] but found [Clear],
	expected [60] but found [55],
	expected [11] but found [12],
	expected [SW] but found [NW],
	Test Failed
	at org.testng.asserts.SoftAssert.assertAll(SoftAssert.java:43)
	at com.testcases.Day8.test(Day8.java:203)
	at sun.reflect.NativeMethodAccessorImpl.invoke0(Native Method)
	at sun.reflect.NativeMethodAccessorImpl.invoke(Unknown Source)
	at sun.reflect.DelegatingMethodAccessorImpl.invoke(Unknown Source)
	at java.lang.reflect.Method.invoke(Unknown Source)
	at org.testng.internal.MethodInvocationHelper.invokeMethod(MethodInvocationHelper.java:104)
	at org.testng.internal.Invoker.invokeMethod(Invoker.java:645)
	at org.testng.internal.Invoker.invokeTestMethod(Invoker.java:851)
	at org.testng.internal.Invoker.invokeTestMethods(Invoker.java:1177)
	at org.testng.internal.TestMethodWorker.invokeTestMethods(TestMethodWorker.java:129)
	at org.testng.internal.TestMethodWorker.run(TestMethodWorker.java:112)
	at org.testng.TestRunner.privateRun(TestRunner.java:756)
	at org.testng.TestRunner.run(TestRunner.java:610)
	at org.testng.SuiteRunner.runTest(SuiteRunner.java:387)
	at org.testng.SuiteRunner.runSequentially(SuiteRunner.java:382)
	at org.testng.SuiteRunner.privateRun(SuiteRunner.java:340)
	at org.testng.SuiteRunner.run(SuiteRunner.java:289)
	at org.testng.SuiteRunnerWorker.runSuite(SuiteRunnerWorker.java:52)
	at org.testng.SuiteRunnerWorker.run(SuiteRunnerWorker.java:86)
	at org.testng.TestNG.runSuitesSequentially(TestNG.java:1293)
	at org.testng.TestNG.runSuitesLocally(TestNG.java:1218)
	at org.testng.TestNG.runSuites(TestNG.java:1133)
	at org.testng.TestNG.run(TestNG.java:1104)
	at org.testng.remote.AbstractRemoteTestNG.run(AbstractRemoteTestNG.java:114)
	at org.testng.remote.RemoteTestNG.initAndRun(RemoteTestNG.java:251)
	at org.testng.remote.RemoteTestNG.main(RemoteTestNG.java:77)
]]>
            </full-stacktrace>
          </exception> <!-- java.lang.AssertionError -->
          <reporter-output>
          </reporter-output>
        </test-method> <!-- test -->
        <test-method status="PASS" signature="closeBrowser()[pri:0, instance:com.testcases.Day8@598067a5]" name="closeBrowser" is-config="true" duration-ms="1530" started-at="2018-04-20T05:04:03Z" finished-at="2018-04-20T05:04:04Z">
          <reporter-output>
          </reporter-output>
        </test-method> <!-- closeBrowser -->
      </class> <!-- com.testcases.Day8 -->
    </test> <!-- Day8 -->
    <test name="Day9" duration-ms="17984" started-at="2018-04-20T09:04:04Z" finished-at="2018-04-20T09:04:22Z">
      <class name="com.testcases.Day9">
        <test-method status="FAIL" signature="test()[pri:0, instance:com.testcases.Day9@42dafa95]" name="test" duration-ms="16446" started-at="2018-04-20T05:04:04Z" finished-at="2018-04-20T05:04:21Z">
          <exception class="java.lang.AssertionError">
            <message>
              <![CDATA[The following asserts failed:
	expected [57] but found [60],
	expected [Mostly Sunny] but found [Clear],
	expected [63] but found [52],
	expected [13] but found [12],
	expected [WSW] but found [NNW]]]>
            </message>
            <full-stacktrace>
              <![CDATA[java.lang.AssertionError: The following asserts failed:
	expected [57] but found [60],
	expected [Mostly Sunny] but found [Clear],
	expected [63] but found [52],
	expected [13] but found [12],
	expected [WSW] but found [NNW]
	at org.testng.asserts.SoftAssert.assertAll(SoftAssert.java:43)
	at com.testcases.Day9.test(Day9.java:203)
	at sun.reflect.NativeMethodAccessorImpl.invoke0(Native Method)
	at sun.reflect.NativeMethodAccessorImpl.invoke(Unknown Source)
	at sun.reflect.DelegatingMethodAccessorImpl.invoke(Unknown Source)
	at java.lang.reflect.Method.invoke(Unknown Source)
	at org.testng.internal.MethodInvocationHelper.invokeMethod(MethodInvocationHelper.java:104)
	at org.testng.internal.Invoker.invokeMethod(Invoker.java:645)
	at org.testng.internal.Invoker.invokeTestMethod(Invoker.java:851)
	at org.testng.internal.Invoker.invokeTestMethods(Invoker.java:1177)
	at org.testng.internal.TestMethodWorker.invokeTestMethods(TestMethodWorker.java:129)
	at org.testng.internal.TestMethodWorker.run(TestMethodWorker.java:112)
	at org.testng.TestRunner.privateRun(TestRunner.java:756)
	at org.testng.TestRunner.run(TestRunner.java:610)
	at org.testng.SuiteRunner.runTest(SuiteRunner.java:387)
	at org.testng.SuiteRunner.runSequentially(SuiteRunner.java:382)
	at org.testng.SuiteRunner.privateRun(SuiteRunner.java:340)
	at org.testng.SuiteRunner.run(SuiteRunner.java:289)
	at org.testng.SuiteRunnerWorker.runSuite(SuiteRunnerWorker.java:52)
	at org.testng.SuiteRunnerWorker.run(SuiteRunnerWorker.java:86)
	at org.testng.TestNG.runSuitesSequentially(TestNG.java:1293)
	at org.testng.TestNG.runSuitesLocally(TestNG.java:1218)
	at org.testng.TestNG.runSuites(TestNG.java:1133)
	at org.testng.TestNG.run(TestNG.java:1104)
	at org.testng.remote.AbstractRemoteTestNG.run(AbstractRemoteTestNG.java:114)
	at org.testng.remote.RemoteTestNG.initAndRun(RemoteTestNG.java:251)
	at org.testng.remote.RemoteTestNG.main(RemoteTestNG.java:77)
]]>
            </full-stacktrace>
          </exception> <!-- java.lang.AssertionError -->
          <reporter-output>
          </reporter-output>
        </test-method> <!-- test -->
        <test-method status="PASS" signature="closeBrowser()[pri:0, instance:com.testcases.Day9@42dafa95]" name="closeBrowser" is-config="true" duration-ms="1535" started-at="2018-04-20T05:04:21Z" finished-at="2018-04-20T05:04:22Z">
          <reporter-output>
          </reporter-output>
        </test-method> <!-- closeBrowser -->
      </class> <!-- com.testcases.Day9 -->
    </test> <!-- Day9 -->
    <test name="Day10" duration-ms="16018" started-at="2018-04-20T09:04:22Z" finished-at="2018-04-20T09:04:38Z">
      <class name="com.testcases.Day10">
        <test-method status="FAIL" signature="test()[pri:0, instance:com.testcases.Day10@7085bdee]" name="test" duration-ms="14532" started-at="2018-04-20T05:04:22Z" finished-at="2018-04-20T05:04:37Z">
          <exception class="java.lang.AssertionError">
            <message>
              <![CDATA[The following asserts failed:
	expected [53] but found [59],
	expected [Mostly Sunny] but found [Clear],
	expected [65] but found [56],
	expected [12] but found [11]]]>
            </message>
            <full-stacktrace>
              <![CDATA[java.lang.AssertionError: The following asserts failed:
	expected [53] but found [59],
	expected [Mostly Sunny] but found [Clear],
	expected [65] but found [56],
	expected [12] but found [11]
	at org.testng.asserts.SoftAssert.assertAll(SoftAssert.java:43)
	at com.testcases.Day10.test(Day10.java:203)
	at sun.reflect.NativeMethodAccessorImpl.invoke0(Native Method)
	at sun.reflect.NativeMethodAccessorImpl.invoke(Unknown Source)
	at sun.reflect.DelegatingMethodAccessorImpl.invoke(Unknown Source)
	at java.lang.reflect.Method.invoke(Unknown Source)
	at org.testng.internal.MethodInvocationHelper.invokeMethod(MethodInvocationHelper.java:104)
	at org.testng.internal.Invoker.invokeMethod(Invoker.java:645)
	at org.testng.internal.Invoker.invokeTestMethod(Invoker.java:851)
	at org.testng.internal.Invoker.invokeTestMethods(Invoker.java:1177)
	at org.testng.internal.TestMethodWorker.invokeTestMethods(TestMethodWorker.java:129)
	at org.testng.internal.TestMethodWorker.run(TestMethodWorker.java:112)
	at org.testng.TestRunner.privateRun(TestRunner.java:756)
	at org.testng.TestRunner.run(TestRunner.java:610)
	at org.testng.SuiteRunner.runTest(SuiteRunner.java:387)
	at org.testng.SuiteRunner.runSequentially(SuiteRunner.java:382)
	at org.testng.SuiteRunner.privateRun(SuiteRunner.java:340)
	at org.testng.SuiteRunner.run(SuiteRunner.java:289)
	at org.testng.SuiteRunnerWorker.runSuite(SuiteRunnerWorker.java:52)
	at org.testng.SuiteRunnerWorker.run(SuiteRunnerWorker.java:86)
	at org.testng.TestNG.runSuitesSequentially(TestNG.java:1293)
	at org.testng.TestNG.runSuitesLocally(TestNG.java:1218)
	at org.testng.TestNG.runSuites(TestNG.java:1133)
	at org.testng.TestNG.run(TestNG.java:1104)
	at org.testng.remote.AbstractRemoteTestNG.run(AbstractRemoteTestNG.java:114)
	at org.testng.remote.RemoteTestNG.initAndRun(RemoteTestNG.java:251)
	at org.testng.remote.RemoteTestNG.main(RemoteTestNG.java:77)
]]>
            </full-stacktrace>
          </exception> <!-- java.lang.AssertionError -->
          <reporter-output>
          </reporter-output>
        </test-method> <!-- test -->
        <test-method status="PASS" signature="closeBrowser()[pri:0, instance:com.testcases.Day10@7085bdee]" name="closeBrowser" is-config="true" duration-ms="1484" started-at="2018-04-20T05:04:37Z" finished-at="2018-04-20T05:04:38Z">
          <reporter-output>
          </reporter-output>
        </test-method> <!-- closeBrowser -->
      </class> <!-- com.testcases.Day10 -->
    </test> <!-- Day10 -->
  </suite> <!-- Suite -->
</testng-results>
